<?xml version="1.0"?>
<robot name="simple_robot">

  <!-- 底盘 -->
  <link name="base_link">
    <visual>
      <geometry>
        <box size="0.4 0.2 0.15"/>
      </geometry>
      <material name="blue">
        <color rgba="0 0 1 1"/>
      </material>
    </visual>
    <collision>
      <geometry>
        <box size="0.4 0.2 0.15"/>
      </geometry>
    </collision>
    <inertial>
      <mass value="5"/>
      <inertia ixx="0.1" ixy="0" ixz="0" iyy="0.1" iyz="0" izz="0.1"/>
    </inertial>
  </link>

  <!-- 左普通轮 -->
  <link name="wheel_left_link">
    <visual>
      <geometry>
        <cylinder radius="0.08" length="0.04"/>
      </geometry>
      <material name="black"/>
    </visual>
    <collision>
      <geometry>
        <cylinder radius="0.08" length="0.04"/>
      </geometry>
    </collision>
    <inertial>
      <mass value="1"/>
      <inertia ixx="0.01" ixy="0" ixz="0" iyy="0.01" iyz="0" izz="0.01"/>
    </inertial>
  </link>
  <joint name="wheel_left_joint" type="continuous">
    <parent link="base_link"/>
    <child link="wheel_left_link"/>
    <origin xyz="0 0.1 0" rpy="1.5780 0 0"/>
    <axis xyz="0 0 1"/>
  </joint>

  <!-- 右普通轮 -->
  <link name="wheel_right_link">
    <visual>
      <geometry>
        <cylinder radius="0.08" length="0.04"/>
      </geometry>
      <material name="black"/>
    </visual>
    <collision>
      <geometry>
        <cylinder radius="0.08" length="0.04"/>
      </geometry>
    </collision>
    <inertial>
      <mass value="1"/>
      <inertia ixx="0.01" ixy="0" ixz="0" iyy="0.01" iyz="0" izz="0.01"/>
    </inertial>
  </link>
  <joint name="wheel_right_joint" type="continuous">
    <parent link="base_link"/>
    <child link="wheel_right_link"/>
    <origin xyz="0 -0.1 0" rpy="1.5780 0 0"/>
    <axis xyz="0 0 1"/>
  </joint>

  <!-- 万向轮 -->
  <link name="caster_link">
    <visual>
      <geometry>
        <sphere radius="0.05"/>
      </geometry>
      <material name="gray">
        <color rgba="0.5 0.5 0.5 1"/>
      </material>
    </visual>
    <collision>
      <geometry>
        <sphere radius="0.05"/>
      </geometry>
    </collision>
    <inertial>
      <mass value="0.5"/>
      <inertia ixx="0.001" ixy="0" ixz="0" iyy="0.001" iyz="0" izz="0.001"/>
    </inertial>
  </link>
  <joint name="caster_joint" type="fixed">
    <parent link="base_link"/>
    <child link="caster_link"/>
    <origin xyz="0.2 0 -0.075"/>
  </joint>


  <gazebo>
    <plugin name="diff_drive" filename="libgazebo_ros_diff_drive.so">
      <updateRate>50</updateRate>
      <leftJoint>wheel_left_joint</leftJoint>
      <rightJoint>wheel_right_joint</rightJoint>
      <wheelSeparation>0.2</wheelSeparation>
      <wheelDiameter>0.16</wheelDiameter>
      <commandTopic>cmd_vel</commandTopic>
      <odometryTopic>odom</odometryTopic>
      <odometryFrame>odom</odometryFrame>
      <robotBaseFrame>base_link</robotBaseFrame>
    </plugin>
  </gazebo>

</robot>
