<?xml version="1.0"?>
<robot xmlns:xacro="http://wiki.ros.org/xacro" name="simple_robot">

    <!-- 全局材质 -->
    <material name="black">
        <color rgba="0 0 0 1"/>
    </material>
    <material name="blue">
        <color rgba="0 0 1 1"/>
    </material>
    <material name="gray">
        <color rgba="0.5 0.5 0.5 1"/>
    </material>
    <material name="white">
        <color rgba="1 1 1 1"/>
    </material>

    <!-- 参数 -->
    <xacro:property name="base_length" value="0.4" />
    <xacro:property name="base_width" value="0.2" />
    <xacro:property name="base_height" value="0.15" />
    <xacro:property name="base_mass" value="5" />

    <xacro:property name="wheel_radius" value="0.08" />
    <xacro:property name="wheel_length" value="0.04" />
    <xacro:property name="wheel_mass" value="1" />

    <xacro:property name="caster_radius" value="0.05" />
    <xacro:property name="caster_mass" value="0.5" />

    <xacro:property name="wheel_sep" value="0.2" />
    <xacro:property name="wheel_diam" value="0.16" />

    <!-- 轮子宏：圆柱体旋转使轴线水平，绕 Y 轴旋转驱动 -->
    <xacro:macro name="wheel" params="prefix reflect">
        <link name="${prefix}_link">
            <visual>
                <geometry>
                    <cylinder radius="${wheel_radius}" length="${wheel_length}" />
                </geometry>
                <material name="black"/>
                <!-- 将圆柱体从默认 Z 轴方向旋转到 Y 轴方向：绕 X 轴旋转 90° -->
                <origin rpy="1.5708 0 0"/>
            </visual>
            <collision>
                <geometry>
                    <cylinder radius="${wheel_radius}" length="${wheel_length}" />
                </geometry>
                <origin rpy="1.5708 0 0"/>
                <surface>
                    <friction>
                        <ode>
                            <mu>100</mu>
                            <mu2>100</mu2>
                        </ode>
                    </friction>
                </surface>
            </collision>
            <inertial>
                <mass value="${wheel_mass}"/>
                <inertia ixx="0.01" ixy="0" ixz="0" iyy="0.01" iyz="0" izz="0.01"/>
            </inertial>
        </link>

        <joint name="${prefix}_joint" type="continuous">
            <parent link="base_link"/>
            <child link="${prefix}_link"/>
            <!-- 轮子安装在底盘两侧，中心与底盘中心同高 -->
            <origin xyz="0 ${reflect * (base_width/2)} 0" rpy="0 0 0"/>
            <axis xyz="0 1 0"/>   <!-- 绕水平 Y 轴旋转，实现滚动 -->
        </joint>
    </xacro:macro>

    <!-- 调用轮子宏 -->
    <xacro:wheel prefix="wheel_left" reflect="1"/>
    <xacro:wheel prefix="wheel_right" reflect="-1"/>

    <!-- 激光雷达 -->
    <xacro:macro name="laser" params="prefix">
        <link name="${prefix}_link">
            <visual>
                <geometry>
                    <cylinder radius="0.05" length="0.15"/>
                </geometry>
                <material name="white"/>
            </visual>
            <collision>
                <geometry>
                    <cylinder radius="0.05" length="0.15"/>
                </geometry>
            </collision>
        </link>
    </xacro:macro>

    <xacro:laser prefix="laser"/>
    <joint name="laser_joint" type="fixed">
        <parent link="base_link"/>
        <child link="laser_link"/>
        <origin xyz="0.15 0 0.075"/>
    </joint>

    <!-- 底盘 -->
    <link name="base_link">
        <visual>
            <geometry>
                <box size="${base_length} ${base_width} ${base_height}"/>
            </geometry>
            <material name="blue"/>
        </visual>
        <collision>
            <geometry>
                <box size="${base_length} ${base_width} ${base_height}"/>
            </geometry>
        </collision>
        <inertial>
            <mass value="${base_mass}"/>
            <inertia ixx="0.1" ixy="0" ixz="0" iyy="0.1" iyz="0" izz="0.1"/>
        </inertial>
    </link>

    <!-- 万向轮：球体下缘接触地面，稳定支撑车体 -->
    <link name="caster_link">
        <visual>
            <geometry>
                <sphere radius="${caster_radius}"/>
            </geometry>
            <material name="gray"/>
        </visual>
        <collision>
            <geometry>
                <sphere radius="${caster_radius}"/>
            </geometry>
        </collision>
    </link>
    <joint name="caster_joint" type="fixed">
        <parent link="base_link"/>
        <child link="caster_link"/>
        <!-- 计算使球体下缘刚好接触地面的偏移：
             整体抬升后 base_link 中心 Z = wheel_radius，
             球心世界 Z = caster_radius 时下缘触地，
             因此相对 base_link 的 Z 偏移 = caster_radius - wheel_radius = -0.03 -->
        <origin xyz="0.2 0 -0.03"/>
    </joint>

    <!-- 差速驱动插件 -->
    <gazebo>
        <plugin name="diff_drive" filename="libgazebo_ros_diff_drive.so">
            <updateRate>50</updateRate>
            <leftJoint>wheel_left_joint</leftJoint>
            <rightJoint>wheel_right_joint</rightJoint>
            <wheelSeparation>${wheel_sep}</wheelSeparation>
            <wheelDiameter>${wheel_diam}</wheelDiameter>
            <wheelTorque>20</wheelTorque>
            <wheelAcceleration>5</wheelAcceleration>
            <commandTopic>/cmd_vel</commandTopic>
            <odometryTopic>/odom</odometryTopic>
            <odometryFrame>odom</odometryFrame>
            <robotBaseFrame>base_link</robotBaseFrame>
        </plugin>
    </gazebo>

    <!-- 全局位姿：将底盘抬高，使轮子下缘刚好接触地面 -->
    <gazebo>
        <pose>0 0 ${wheel_radius} 0 0 0</pose>
    </gazebo>

</robot>
